<mujoco model="linearparticle">

    <compiler inertiafromgeom="true" angle="radian" coordinate="local" />
    <option timestep="0.01" gravity="0 0 0" iterations="20" integrator="Euler" />
    <default>
        <joint limited="false" damping="1" />
        <geom contype="2" conaffinity="1" condim="1" friction=".5 .1 .1" density="1000" margin="0.002" />
    </default>

    <worldbody>
        <body name="particle" pos="0 0 0">
            <geom name="particle_geom" type="capsule" fromto="-0.01 0 0 0.01 0 0" size="0.05" />
            <site name="particle_site" pos="0 0 0" size="0.01" />
            <joint name="ball_x" type="slide" limited="true" range="-1 1" pos="0 0 0" axis="1 0 0" />
            <joint name="ball_y" type="slide" limited="true" range="-1 1" pos="0 0 0" axis="0 1 0" />
        </body>
       <!-- Arena -->
		<geom conaffinity="0" fromto="-1.1 -1.1 .01 1.1 -1.1 .01" name="sideS" rgba="0.9 0.4 0.6 1" size=".02" type="capsule"/>
		<geom conaffinity="0" fromto=" 1.1 -1.1 .01 1.1  1.1 .01" name="sideE" rgba="0.9 0.4 0.6 1" size=".02" type="capsule"/>
		<geom conaffinity="0" fromto="-1.1  1.1 .01 1.1  1.1 .01" name="sideN" rgba="0.9 0.4 0.6 1" size=".02" type="capsule"/>
		<geom conaffinity="0" fromto="-1.1 -1.1 .01 -1.1 1.1 .01" name="sideW" rgba="0.9 0.4 0.6 1" size=".02" type="capsule"/>
    </worldbody>

    <actuator>
        <motor joint="ball_x" ctrlrange="-1 1" ctrllimited="true"/>
        <motor joint="ball_y" ctrlrange="-1 1" ctrllimited="true"/>
    </actuator>
</mujoco>